Workbook

Sheet PANDUAN
A1: PANDUAN PENGGUNAAN — INSTRUMEN KEUANGAN LAMEMBA (PREDIKAT PERHATIAN)
A3: KONTEKS DAN ASUMSI DATA — PREDIKAT PERHATIAN
A4: Institusi | B4: PTS Kecil-Menengah, Kota Tier 2/3 atau Pulau Jawa — Tahun Akademik 2024/2025
A5: Jumlah Mahasiswa TS | B5: 2.800 FTE (TS), 2.600 FTE (TS-1), 2.400 FTE (TS-2) — pertumbuhan lambat ~8%/tahun
A6: SPP / UKT | B6: Rp 6.000.000/semester = Rp 12.000.000/tahun. SPP Gross = 2.800 × Rp 12 jt = Rp 33,6 Miliar
A7: Beasiswa / Discount Rate | B7: 28% — lebih tinggi dari BAIK, segmen mahasiswa lebih price-sensitive. Net SPP = Rp 24,2 M
A8: Total Pendapatan TS | B8: Rp 41.392.000.000 (Rp 41,4 Miliar) — Rp 14,8 jt/mhs/thn (sangat bergantung SPP)
A9: Total Pengeluaran TS | B9: Rp 41.150.000.000 (Rp 41,2 Miliar) — Operating Margin hanya 0,58% (sangat tipis!)
A10: Jumlah Dosen Tetap | B10: 185 dosen FTE — Rasio Dosen-Mahasiswa 15,1:1 (masih dalam range aman)
A11: Sinyal Perhatian | B11: Margin tipis, utang relatif besar, investasi SDM & sarpras rendah, endowment sangat kecil.
A13: PERBANDINGAN TIGA PREDIKAT — HIERARKI RASIONAL
A14: Mahasiswa FTE | B14: 6.000 | C14: BAIK: 4.200 | PERHATIAN: 2.800
A15: SPP/semester | B15: Rp 10 juta | C15: BAIK: Rp 8 juta | PERHATIAN: Rp 6 juta
A16: Total Pendapatan | B16: Rp 175 M | C16: BAIK: Rp 90,8 M | PERHATIAN: Rp 41,4 M
A17: Operating Margin | B17: 5,20% | C17: BAIK: 2,64% | PERHATIAN: 0,58% ⚠️
A18: Tuition Dependency | B18: 51,4% | C18: BAIK: 55,5% | PERHATIAN: 58,5% ⚠️
A19: Endowment | B19: Rp 112 M | C19: BAIK: Rp 42 M | PERHATIAN: Rp 8 M ⚠️
A20: Days Cash | B20: 154 hari | C20: BAIK: 140 hari | PERHATIAN: 159 hari ✓
A21: ICR | B21: 11,92× | C21: BAIK: 3,93× | PERHATIAN: 1,78× ⚠️
A22: DSCR | B22: 3,82× | C22: BAIK: 2,11× | PERHATIAN: 1,29× ⚠️
A23: LAMEMBA terpenuhi | B23: 8/10 | C23: BAIK: 6/10 | PERHATIAN: 4-5/10 ⚠️
A25: 10 INDIKATOR LAMEMBA — STATUS PREDIKAT PERHATIAN
A26: L1 | B26: Rasio Kemandirian (RK) (≥ 30%) | C26: ✓ 86,71% — masih terpenuhi ✓
A27: L2 | B27: Rasio Efisiensi Operasional (REO) (≥ 65%) | C27: ✗ 58,32% — belum terpenuhi (struktural) ✗
A28: L3 | B28: Varians Anggaran (VA) (≤ ±10%) | C28: ✓ 7,59% — terpenuhi tapi mendekati batas ✓
A29: L4 | B29: Rasio Investasi SDM (RISDM) (≥ 15%) | C29: ✗ 12,64% — tidak terpenuhi, investasi SDM minimal ✗
A30: L5 | B30: Rasio Investasi Sarpras (RISP) (≥ 20%) | C30: ✗ 11,18% — tidak terpenuhi, infrastruktur kritis ✗
A31: L6 | B31: Pertumbuhan Pendapatan (GRR) (≥ 5%) | C31: ✓ 9,78% — terpenuhi, namun pertumbuhan hanya dari SPP ✓
A32: L7 | B32: Biaya per Mahasiswa (RBM) (Sesuai SPMI) | C32: — Rp 14,7 jt/mhs/thn — validasi SPMI setempat
A33: L8 | B33: Indeks Keberlanjutan (IKK) (≥ 2.5 (0–4)) | C33: ✓ ≈ 2.57 — tepat di atas batas minimum ✓
A34: L9 | B34: Rasio Likuiditas (RL) (≥ 100% (≥1.0×)) | C34: ✓ 1,74× — terpenuhi ✓
A35: L10 | B35: Alokasi Tridharma (ATT) (Proporsional) | C35: ✓ Pend58%/Rist28%/PkM14% — deviasi < 10% ✓
A37: REKOMENDASI PERBAIKAN — PRIORITAS UTAMA
A38: P1 | B38: Diversifikasi Pendapatan | C38: Kurangi ketergantungan SPP (58% → target <50%). Kembangkan riset, auxiliary, donasi alumni.
A39: P2 | B39: Tingkatkan RISDM ≥15% | C39: Tambah anggaran SDM Rp ~1 M (dari 5,2M → 6,2M). Prioritaskan pelatihan dosen produktif.
A40: P3 | B40: Tingkatkan RISP ≥20% | C40: Tambah investasi sarpras Rp ~3,6 M. Gunakan pinjaman produktif jika perlu.
A41: P4 | B41: Perkuat Endowment | C41: Kampanye wakaf/donasi alumni. Target endowment ≥ 2× total utang dalam 5 tahun.
A42: P5 | B42: Kendalikan Utang | C42: ICR 1,78× dan DSCR 1,29× mendekati batas kritis. Hindari utang baru tanpa rencana bayar jelas.
A43: P6 | B43: Tingkatkan Operating Margin | C43: Margin 0,58% sangat rentan. Target 3-5% melalui efisiensi + pertumbuhan pendapatan non-SPP.

Sheet INPUT DATA
A1: INSTRUMEN KEUANGAN LAMEMBA — DATA INPUT (PREDIKAT PERHATIAN)
A2: ⚠️ PERHATIAN: Operating Margin hanya 0,58%. Isi HANYA sel BIRU. Formula latar biru-muda otomatis.
A4: A. DATA PENDAPATAN (Rupiah)
A5: Komponen Pendapatan | B5: TS (Tahun Ini) | C5: TS-1 (Tahun Lalu) | D5: TS-2 (2 Thn Lalu) | E5: Keterangan
A6: Pendapatan SPP / Biaya Kuliah Gross (UKT) | B6: 33600000000 | C6: 31200000000 | D6: 28800000000 | E6: 2.800 mhs × Rp 12 jt/thn = Rp 33,6 M TS. (Rp 6 jt/semester × 2 sem).
A7: Beasiswa & Financial Aid (pengurang, nilai NEGATIF) | B7: -9408000000 | C7: -8736000000 | D7: -8064000000 | E7: 28% discount rate — lebih tinggi dari BAIK karena segmen mahasiswa lebih price-sensitive.
A8: Pendapatan Pemerintah (BOPTN, hibah institusi) | B8: 5500000000 | C8: 5100000000 | D8: 4700000000 | E8: BOPTN lebih besar proporsinya vs total pendapatan — ketergantungan subsidi lebih tinggi.
A9: Pendapatan Penelitian & Hibah Kompetitif | B9: 4200000000 | C9: 3600000000 | D9: 3100000000 | E9: Riset terbatas — kapasitas dosen peneliti lebih kecil. Perlu dikembangkan.
A10: Pendapatan Donasi & Sumbangan (Gifts) | B10: 2000000000 | C10: 1700000000 | D10: 1450000000 | E10: Alumni network lemah. Fundraising belum terstruktur.
A11: Pendapatan Auxiliary (usaha penunjang) | B11: 3800000000 | C11: 3400000000 | D11: 2900000000 | E11: Kantin, parkir, koperasi kecil. Potensi besar yang belum dioptimalkan.
A12: Pendapatan Investasi Endowment (operasional) | B12: 800000000 | C12: 680000000 | D12: 580000000 | E12: Endowment sangat kecil (Rp 8 M). Return minimal. Perlu strategi pengembangan dana abadi.
A13: Pendapatan Lain-lain | B13: 900000000 | C13: 760000000 | D13: 650000000 | E13: Sertifikasi, event, dll.
A14: → Net Tuition Revenue (SPP − Beasiswa) | B14: =B6+B7 -> 24192000000 | C14: =C6+C7 -> 22464000000 | D14: =D6+D7 -> 20736000000 | E14: Formula otomatis
A15: → Pendapatan Non-Pemerintah (Non-Subsidi) | B15: =B6+B7+B9+B10+B11+B12+B13 -> 35892000000 | C15: =C6+C7+C9+C10+C11+C12+C13 -> 32604000000 | D15: =D6+D7+D9+D10+D11+D12+D13 -> 29416000000 | E15: Formula otomatis
A16: TOTAL PENDAPATAN | B16: =SUM(B6:B13) -> 41392000000 | C16: =SUM(C6:C13) -> 37704000000 | D16: =SUM(D6:D13) -> 34116000000
A18: B. DATA PENGELUARAN (Rupiah)
A19: Komponen Pengeluaran | B19: TS (Tahun Ini) | C19: TS-1 (Tahun Lalu) | D19: TS-2 (2 Thn Lalu) | E19: Keterangan
A20: Biaya Operasional Langsung (Pendidikan, Penelitian, PkM) | B20: 24000000000 | C20: 21000000000 | D20: 18200000000 | E20: Tridharma. REO=58,32% — mendekati 65% tapi belum. Jauh lebih kecil dari BAIK.
A21: Biaya Administrasi & Institutional Support | B21: 3800000000 | C21: 3400000000 | D21: 2960000000 | E21: Admin ratio 9,24% — relatif tinggi vs pendapatan kecil. Efisiensi overhead perlu ditingkatkan.
A22: Biaya Instruksi / Pengajaran (INFO — subset dari B20) | B22: 19200000000 | C22: 16800000000 | D22: 14560000000 | E22: INFO SAJA — sudah termasuk dalam B20. TIDAK dihitung di Total Pengeluaran.
A23: Anggaran Pengembangan SDM (pelatihan, riset, hibah) | B23: 5200000000 | C23: 4600000000 | D23: 4000000000 | E23: RISDM=12,64% — belum ≥15%. Investasi SDM minimal karena tekanan keuangan.
A24: Belanja Aset Tetap / CapEx (gedung, lab, IT) | B24: 2800000000 | C24: 2500000000 | D24: 2200000000 | E24: CapEx sangat kecil. RISP=(2,8+1,8)/41,15=11,18% — jauh dari target ≥20%.
A25: Biaya Pemeliharaan Sarana Prasarana | B25: 1800000000 | C25: 1600000000 | D25: 1400000000 | E25: Pemeliharaan minimal — risiko degradasi aset jangka panjang.
A26: Gaji & Tunjangan Dosen Tetap (tunjangan akademik) | B26: 700000000 | C26: 640000000 | D26: 570000000 | E26: Sangat kecil — tunjangan terbatas karena tekanan keuangan.
A27: Depresiasi / Penyusutan Aset | B27: 1000000000 | C27: 900000000 | D27: 800000000 | E27: Non-kas. Aset lebih kecil dari BAIK.
A28: Beban Bunga (Interest Expense) | B28: 1600000000 | C28: 1480000000 | D28: 1350000000 | E28: Bunga relatif besar terhadap EBITDA. ICR=1,78× — di bawah ideal ≥3×.
A29: Biaya Lain-lain Operasional | B29: 250000000 | C29: 220000000 | D29: 190000000
A30: TOTAL PENGELUARAN | B30: =SUM(B20:B21)+SUM(B23:B29) -> 41150000000 | C30: =SUM(C20:C21)+SUM(C23:C29) -> 36340000000 | D30: =SUM(D20:D21)+SUM(D23:D29) -> 31670000000
A32: C. DATA NERACA KEUANGAN (Rupiah)
A33: Komponen Neraca | B33: TS (Tahun Ini) | C33: TS-1 (Tahun Lalu) | D33: TS-2 (2 Thn Lalu) | E33: Keterangan
A34: Kas & Setara Kas | B34: 10500000000 | C34: 9100000000 | D34: 7900000000 | E34: TS: Rp 10,5 M — Days Cash=159 hari ✓. Relatif aman meski margin tipis.
A35: Investasi Jangka Pendek (< 1 tahun) | B35: 7500000000 | C35: 6500000000 | D35: 5650000000 | E35: Rp 7,5 M.
A36: Piutang Bersih | B36: 5200000000 | C36: 4600000000 | D36: 4100000000 | E36: Piutang tinggi relatif terhadap pendapatan — perlu penguatan penagihan.
A37: Aset Lancar Lainnya | B37: 1200000000 | C37: 1050000000 | D37: 920000000
A38: Total Aset Tetap (Neto setelah depresiasi) | B38: 58000000000 | C38: 52500000000 | D38: 47500000000 | E38: Aset tetap kecil (Rp 58 M). Investasi terbatas → fasilitas lebih tua.
A39: Endowment / Dana Abadi (nilai pasar) | B39: 8000000000 | C39: 6900000000 | D39: 5900000000 | E39: ⚠️ Endowment sangat kecil: Rp 8 M. Endow/Debt=0,36× — di bawah ≥1,0×. Perlu dikembangkan.
A40: Total Aset | B40: =SUM(B34:B39) -> 90400000000 | C40: =SUM(C34:C39) -> 80650000000 | D40: =SUM(D34:D39) -> 71970000000 | E40: Total Aset Lancar + Aset Tetap + Endowment
A41: Kewajiban Jangka Pendek | B41: 14000000000 | C41: 12500000000 | D41: 11000000000 | E41: RL=1,74× ✓. Masih aman tapi lebih rendah dari BAIK (2,39×).
A42: Kewajiban Jangka Panjang / Total Utang | B42: 22000000000 | C42: 20000000000 | D42: 18000000000 | E42: ⚠️ Utang Rp 22 M cukup besar. Debt/Assets=24,3% (mendekati batas 25%). Hati-hati ekspansi.
A43: Expendable Net Assets | B43: 18000000000 | C43: 15500000000 | D43: 13200000000 | E43: Primary Reserve=18/41,15=0,44 ✓ (di atas minimum 0,17). Viability=0,82× ✓.
...

Sheet HASIL RASIO
A1: HASIL PERHITUNGAN — SEMUA RASIO KESEHATAN KEUANGAN UNIVERSITAS (PREDIKAT PERHATIAN)
A2: ⚠️ PERHATIAN = beberapa rasio mendekati atau melewati ambang batas. ★ = LAMEMBA | Hijau=✓ | Merah=✗ | Kuning=Mendekati batas
A3: TABEL 1: COMPOSITE FINANCIAL INDEX (CFI) — Rasio Utama
A4: No | B4: Nama Rasio / Indikator | C4: Formula | D4: Komponen Input | E4: Nilai TS | F4: Nilai TS-1 | G4: Nilai TS-2 | H4: Target Sehat | I4: Target Min/Max | J4: Score (0-100) | K4: Status TS | L4: Keterangan
A5: 1 | B5: Primary Reserve Ratio | C5: Expendable Net Assets ÷ Total Operating Expenses | D5: Expendable NA / Total Pengeluaran | E5: ='INPUT DATA'!B43/'INPUT DATA'!B30 -> 0.43742406 | F5: ='INPUT DATA'!C43/'INPUT DATA'!C30 -> 0.42652724 | G5: ='INPUT DATA'!D43/'INPUT DATA'!D30 -> 0.41679823 | H5: 0.4 | I5: 0.17–0.40 | J5: =IF(E5>=H5,100,IF(E5<=0.17,0,(E5-0.17)/(0.4-0.17)*100)) -> 100 | K5: =IF(E5>0.4,"SEHAT ✓",IF(E5>=0.17,"PERHATIAN","BERISIKO ✗")) -> SEHAT ✓ | L5: ⚠️ PERHATIAN: 0.44 — di atas minimum 0.17 ✓ tapi di bawah target 0.40. Risiko jika pendapatan turun.
A6: 2 | B6: Viability Ratio | C6: Expendable Net Assets ÷ Total Debt | D6: Expendable NA / Total Utang | E6: ='INPUT DATA'!B43/'INPUT DATA'!B42 -> 0.81818182 | F6: ='INPUT DATA'!C43/'INPUT DATA'!C42 -> 0.775 | G6: ='INPUT DATA'!D43/'INPUT DATA'!D42 -> 0.73333333 | H6: 0.35 | I6: 0.20–0.35 | J6: =IF(E6>=H6,100,IF(E6<=0.2,0,(E6-0.2)/(0.35-0.2)*100)) -> 100 | K6: =IF(E6>0.35,"SEHAT ✓",IF(E6>=0.2,"PERHATIAN","BERISIKO ✗")) -> SEHAT ✓ | L6: ⚠️ PERHATIAN: 0.82× — di atas 0.35 ✓ tapi relatif lemah. Tekanan utang terasa.
A7: 3 | B7: Return on Net Assets | C7: Change in Net Assets ÷ Beginning Net Assets | D7: Perubahan Aset Bersih / Aset Bersih Awal | E7: ='INPUT DATA'!B44/'INPUT DATA'!B45 -> 0.014285714 | F7: ='INPUT DATA'!C44/'INPUT DATA'!C45 -> 0.013150685 | G7: ='INPUT DATA'!D44/'INPUT DATA'!D45 -> 0.011949686 | H7: 0.02 | I7: 0%–2% | J7: =IF(E7>=H7,100,IF(E7<=0,0,(E7-0)/(0.2-0)*100)) -> 7.1428571 | K7: =IF(E7>H7,"SEHAT ✓",IF(E7>=0,"PERHATIAN","BERISIKO ✗")) -> PERHATIAN | L7: ⚠️ PERHATIAN: 1,43% — di bawah target 2%. Pertumbuhan kekayaan bersih sangat lambat.
A8: 4 | B8: Net Operating Revenue Ratio | C8: (Op. Revenue − Op. Expenses) ÷ Op. Revenue | D8: (Total Pdpt − Total Pglr) / Total Pdpt | E8: =('INPUT DATA'!B16-'INPUT DATA'!B30)/'INPUT DATA'!B16 -> 0.0058465404 | F8: =('INPUT DATA'!C16-'INPUT DATA'!C30)/'INPUT DATA'!C16 -> 0.036176533 | G8: =('INPUT DATA'!D16-'INPUT DATA'!D30)/'INPUT DATA'!D16 -> 0.071696565 | H8: 0.02 | I8: 0%–2% | J8: =IF(E8>=H8,100,IF(E8<=0,0,(E8-0)/(0.2-0)*100)) -> 2.9232702 | K8: =IF(E8>H8,"SEHAT ✓",IF(E8>=0,"PERHATIAN","BERISIKO ✗")) -> PERHATIAN | L8: ⚠️ PERHATIAN: 0,58% — sangat tipis. Satu tahun buruk bisa langsung defisit.
A9: TABEL 2: RASIO LIKUIDITAS
A10: No | B10: Nama Rasio / Indikator | C10: Formula | D10: Komponen Input | E10: Nilai TS | F10: Nilai TS-1 | G10: Nilai TS-2 | H10: Target Sehat | I10: Target Min/Max | J10: Score (0-100) | K10: Status TS | L10: Keterangan
A11: 5 | B11: Liquidity Ratio | C11: Sources of Liquidity ÷ Uses of Liquidity | D11: Sumber Likuid / Penggunaan Likuid | E11: ='INPUT DATA'!B47/'INPUT DATA'!B48 -> 1.75 | F11: ='INPUT DATA'!C47/'INPUT DATA'!C48 -> 1.7253521 | G11: ='INPUT DATA'!D47/'INPUT DATA'!D48 -> 1.7096774 | H11: 1.25 | I11: 1 | J11: =IF(E11>=H11,100,IF(E11<=1,0,(E11-1)/(H11-1)*100)) -> 100 | K11: =IF(E11>=1.25,"SEHAT ✓",IF(E11>=1,"PERHATIAN","BERISIKO ✗")) -> SEHAT ✓ | L11: PERHATIAN: 1.75× — masih aman ✓ tapi margin lebih tipis dari BAIK.
A12: 6 | B12: Days Cash on Hand | C12: (Kas + Investasi JP) ÷ (Total Pengeluaran / 365) | D12: (Kas+Inv.JP) / (Total Pglr / 365) | E12: =('INPUT DATA'!B34+'INPUT DATA'!B35)/('INPUT DATA'!B30/365) -> 159.65978 | F12: =('INPUT DATA'!C34+'INPUT DATA'!C35)/('INPUT DATA'!C30/365) -> 156.68685 | G12: =('INPUT DATA'!D34+'INPUT DATA'!D35)/('INPUT DATA'!D30/365) -> 156.16514 | H12: 120 | I12: 60 | J12: =IF(E12>=H12,100,IF(E12<=60,0,(E12-60)/(H12-60)*100)) -> 100 | K12: =IF(E12>=120,"SEHAT ✓",IF(E12>=60,"PERHATIAN","BERISIKO ✗")) -> SEHAT ✓ | L12: PERHATIAN: 159 hari — terpenuhi ✓. Kas relatif cukup meski pendapatan kecil.
A13: 7 | B13: Cash to Debt Ratio | C13: Kas & Setara Kas ÷ Total Debt | D13: Kas / Total Utang | E13: ='INPUT DATA'!B34/'INPUT DATA'!B42 -> 0.47727273 | F13: ='INPUT DATA'!C34/'INPUT DATA'!C42 -> 0.455 | G13: ='INPUT DATA'!D34/'INPUT DATA'!D42 -> 0.43888889 | H13: 0.25 | I13: 0.15 | J13: =IF(E13>=H13,100,IF(E13<=0.15,0,(E13-0.15)/(H13-0.15)*100)) -> 100 | K13: =IF(E13>=0.25,"SEHAT ✓",IF(E13>=0.15,"PERHATIAN","BERISIKO ✗")) -> SEHAT ✓ | L13: ⚠️ PERHATIAN: 0.48× — terpenuhi ✓ tapi hanya kira-kira setengah dari utang yang bisa dilunasi dengan kas.
A14: L9 | B14: ★ ★ Rasio Likuiditas (RL) — LAMEMBA | C14: Aset Lancar ÷ Kewajiban Jangka Pendek | D14: Aset Lancar / Kwj. Jangka Pendek | E14: ='INPUT DATA'!B49/'INPUT DATA'!B41 -> 1.7428571 | F14: ='INPUT DATA'!C49/'INPUT DATA'!C41 -> 1.7 | G14: ='INPUT DATA'!D49/'INPUT DATA'!D41 -> 1.6881818 | H14: ≥ 100% | I14: ≥ 100% | J14: =IF(E14>=1,100,IF(E14<=0,0,(E14/1)*100)) -> 100 | K14: =IF(E14>=1,"YA TERPENUHI ✓","BELUM TERPENUHI ✗") -> YA TERPENUHI ✓ | L14: LAMEMBA No.9. PERHATIAN: 1,74× — terpenuhi ✓ tapi lebih rendah dari BAIK (2,39×).
A15: TABEL 3: RASIO EFISIENSI OPERASIONAL
A16: No | B16: Nama Rasio / Indikator | C16: Formula | D16: Komponen Input | E16: Nilai TS | F16: Nilai TS-1 | G16: Nilai TS-2 | H16: Target Sehat | I16: Target Min/Max | J16: Score (0-100) | K16: Status TS | L16: Keterangan
A17: 8 | B17: Operating Margin | C17: (Op. Revenue − Op. Expenses) ÷ Op. Revenue | D17: (Total Pdpt − Total Pglr) / Total Pdpt | E17: =('INPUT DATA'!B16-'INPUT DATA'!B30)/'INPUT DATA'!B16 -> 0.0058465404 | F17: =('INPUT DATA'!C16-'INPUT DATA'!C30)/'INPUT DATA'!C16 -> 0.036176533 | G17: =('INPUT DATA'!D16-'INPUT DATA'!D30)/'INPUT DATA'!D16 -> 0.071696565 | H17: 0.04 | I17: 1%–3% | J17: =IF(E17>=H17,100,IF(E17<=0,0,(E17/H17)*100)) -> 14.616351 | K17: =IF(E17>=H17,"SEHAT ✓",IF(E17>=0,"PERHATIAN","BERISIKO ✗")) -> PERHATIAN | L17: ⚠️ PERHATIAN: 0,58% — sangat tipis. Target minimal 2-3% untuk buffer aman.
A18: 9 | B18: Administrative Expense Ratio | C18: Biaya Administrasi ÷ Total Op. Expenses | D18: Adm & Overhead / Total Pengeluaran | E18: ='INPUT DATA'!B21/'INPUT DATA'!B30 -> 0.092345079 | F18: ='INPUT DATA'!C21/'INPUT DATA'!C30 -> 0.093560815 | G18: ='INPUT DATA'!D21/'INPUT DATA'!D30 -> 0.093463846 | H18: 0.15 | I18: 0.12 | J18: =IF(E18<=H18,100,0) -> 100 | K18: =IF(E18<=H18,"SEHAT ✓",IF(E18>H18,"PERHATIAN","BERISIKO ✗")) -> SEHAT ✓ | L18: ⚠️ PERHATIAN: 9,2% — terpenuhi ✓ tapi terasa besar karena pendapatan kecil. Efisiensi overhead kritis.
A19: 10 | B19: Tuition Dependency Ratio | C19: Net Tuition Revenue ÷ Total Op. Revenue | D19: Net Tuition / Total Pendapatan | E19: ='INPUT DATA'!B14/'INPUT DATA'!B16 -> 0.58446077 | F19: ='INPUT DATA'!C14/'INPUT DATA'!C16 -> 0.59579885 | G19: ='INPUT DATA'!D14/'INPUT DATA'!D16 -> 0.60780865 | H19: 0.5 | I19: 0.7 | J19: =IF(E19<=H19,100,IF(E19>=0.7,0,(E19-0.7)/(H19-0.7)*100)) -> 57.769617 | K19: =IF(E19<0.5,"RISIKO RENDAH ✓",IF(E19<0.7,"RISIKO SEDANG","RISIKO TINGGI ✗")) -> RISIKO SEDANG | L19: ⚠️ PERHATIAN: 58,5% — risiko sedang-tinggi. Bergantung besar pada SPP, rentan jika enrollment turun.
A20: 11 | B20: Cost per Student | C20: Total Operating Expenses ÷ Total FTE Students | D20: Total Pengeluaran / Mahasiswa FTE | E20: ='INPUT DATA'!B30/'INPUT DATA'!B71 -> 14696429 | F20: ='INPUT DATA'!C30/'INPUT DATA'!C71 -> 13976923 | G20: ='INPUT DATA'!D30/'INPUT DATA'!D71 -> 13195833 | H20: Benchmark industri | I20: Benchmark SPMI | K20: "Lihat benchmark SPMI" | L20: PERHATIAN: Rp 14,7 jt/mhs/thn — lebih rendah dari BAIK (Rp 21 jt). Efisiensi baik, tapi risiko kualitas.
A21: L2 | B21: ★ ★ Rasio Efisiensi Operasional (REO) — LAMEMBA | C21: Biaya Operasional Langsung ÷ Total Pengeluaran | D21: Biaya Langsung / Total Pengeluaran | E21: ='INPUT DATA'!B20/'INPUT DATA'!B30 -> 0.58323208 | F21: ='INPUT DATA'!C20/'INPUT DATA'!C30 -> 0.57787562 | G21: ='INPUT DATA'!D20/'INPUT DATA'!D30 -> 0.57467635 | H21: ≥ 65% | I21: ≥ 65% | J21: =IF(E21>=0.65,100,IF(E21<=0.5,0,(E21-0.5)/(0.65-0.5)*100)) -> 55.488052 | K21: =IF(E21>=0.65,"YA TERPENUHI ✓","BELUM TERPENUHI ✗") -> BELUM TERPENUHI ✗ | L21: LAMEMBA No.2. PERHATIAN: 58,32% — belum ≥65% (struktural). Perlu terus ditingkatkan.
A22: L7 | B22: ★ ★ Rasio Biaya per Mahasiswa (RBM) — LAMEMBA | C22: Total Biaya Operasional ÷ Jumlah Mahasiswa Aktif | D22: Total Pengeluaran / Mahasiswa FTE | E22: ='INPUT DATA'!B30/'INPUT DATA'!B71 -> 14696429 | F22: ='INPUT DATA'!C30/'INPUT DATA'!C71 -> 13976923 | G22: ='INPUT DATA'!D30/'INPUT DATA'!D71 -> 13195833 | H22: Sesuai SPMI | I22: Sesuai SPMI | K22: "Lihat standar SPMI institusi" | L22: LAMEMBA No.7. PERHATIAN: Rp 14,7 jt/mhs/thn. Bandingkan dengan standar SPMI setempat.
A23: TABEL 4: RASIO UTANG DAN LEVERAGE
A24: No | B24: Nama Rasio / Indikator | C24: Formula | D24: Komponen Input | E24: Nilai TS | F24: Nilai TS-1 | G24: Nilai TS-2 | H24: Target Sehat | I24: Target Min/Max | J24: Score (0-100) | K24: Status TS | L24: Keterangan
A25: 12 | B25: Debt Service Coverage Ratio | C25: (Op. Income + Depreciation + Interest) ÷ Annual Debt Service | D25: (Net Inc+Depr+Int) / Debt Service | E25: =('INPUT DATA'!B16-'INPUT DATA'!B30+'INPUT DATA'!B27+'INPUT DATA'!B28)/'INPUT DATA'!B46 -> 1.2918182 | F25: =('INPUT DATA'!C16-'INPUT DATA'!C30+'INPUT DATA'!C27+'INPUT DATA'!C28)/'INPUT DATA'!C46 -> 1.872 | G25: =('INPUT DATA'!D16-'INPUT DATA'!D30+'INPUT DATA'!D27+'INPUT DATA'!D28)/'INPUT DATA'!D46 -> 2.5252747 | H25: 2 | I25: 1.25 | J25: =IF(E25>=H25,100,IF(E25<=1.25,0,(E25-1.25)/(H25-1.25)*100)) -> 5.5757576 | K25: =IF(E25>=2,"SEHAT ✓",IF(E25>=1.25,"PERHATIAN","BERISIKO ✗")) -> PERHATIAN | L25: ⚠️ PERHATIAN: 1,29× — di bawah ≥2,0×. Kemampuan membayar utang sangat terbatas. Prioritas utama.
A26: 13 | B26: Debt-to-Assets Ratio | C26: Total Debt ÷ Total Assets | D26: Total Utang / Total Aset | E26: ='INPUT DATA'!B42/'INPUT DATA'!B40 -> 0.24336283 | F26: ='INPUT DATA'!C42/'INPUT DATA'!C40 -> 0.24798512 | G26: ='INPUT DATA'!D42/'INPUT DATA'!D40 -> 0.25010421 | H26: 0.25 | I26: 0.35 | J26: =IF(E26<=H26,100,IF(E26>=0.35,0,(E26-0.35)/(H26-0.35)*100)) -> 100 | K26: =IF(E26<0.25,"SEHAT ✓",IF(E26<0.35,"PERHATIAN","BERISIKO ✗")) -> SEHAT ✓ | L26: ⚠️ PERHATIAN: ~24,3% — mendekati batas 25%. Jangan tambah utang baru tanpa rencana jelas.
A27: 14 | B27: Interest Coverage Ratio | C27: EBITDA ÷ Interest Expense | D27: EBITDA / Beban Bunga | E27: ='INPUT DATA'!B77/'INPUT DATA'!B78 -> 1.77625 | F27: ='INPUT DATA'!C77/'INPUT DATA'!C78 -> 2.5297297 | G27: ='INPUT DATA'!D77/'INPUT DATA'!D78 -> 3.4044444 | H27: 3 | I27: 2 | J27: =IF(E27>=H27,100,IF(E27<=2,0,(E27-2)/(H27-2)*100)) -> 0 | K27: =IF(E27>=3,"SEHAT ✓",IF(E27>=2,"PERHATIAN","BERISIKO ✗")) -> BERISIKO ✗ | L27: ⚠️ PERHATIAN: 1,78× — di bawah target ≥3×. EBITDA kecil, bunga terasa berat.
A28: 15 | B28: Debt per Student | C28: Total Debt ÷ Total FTE Students | D28: Total Utang / Mahasiswa FTE | E28: ='INPUT DATA'!B42/'INPUT DATA'!B71 -> 7857142.9 | F28: ='INPUT DATA'!C42/'INPUT DATA'!C71 -> 7692307.7 | G28: ='INPUT DATA'!D42/'INPUT DATA'!D71 -> 7500000 | H28: Benchmark industri | I28: Benchmark industri | K28: "Lihat benchmark industri" | L28: ⚠️ PERHATIAN: Rp 7,86 jt/mhs — utang per mahasiswa lebih tinggi dari BAIK (Rp 7,14 jt) secara relatif.
A29: TABEL 5: RASIO ENDOWMENT DAN INVESTASI
A30: No | B30: Nama Rasio / Indikator | C30: Formula | D30: Komponen Input | E30: Nilai TS | F30: Nilai TS-1 | G30: Nilai TS-2 | H30: Target Sehat | I30: Target Min/Max | J30: Score (0-100) | K30: Status TS | L30: Keterangan
A31: 16 | B31: Endowment per Student | C31: Total Endowment ÷ Total Enrolled Students | D31: Nilai Endowment / Mahasiswa | E31: ='INPUT DATA'!B39/'INPUT DATA'!B71 -> 2857142.9 | F31: ='INPUT DATA'!C39/'INPUT DATA'!C71 -> 2653846.2 | G31: ='INPUT DATA'!D39/'INPUT DATA'!D71 -> 2458333.3 | H31: Bervariasi | I31: Bervariasi | K31: "Lihat benchmark kategori" | L31: ⚠️ PERHATIAN: Rp 2,86 jt/mhs — sangat rendah. BAIK Rp 10 jt/mhs, SB Rp 18,67 jt/mhs.
A32: 17 | B32: Endowment Spending Rate | C32: Annual Endowment Distribution ÷ Average Market Value (3yr) | D32: Payout / Rata-rata Endowment | E32: ='INPUT DATA'!B74/'INPUT DATA'!B50 -> 0.092307692 | F32: — | G32: — | H32: 4%–8% | I32: 4%–6% | K32: =IF(AND(E32>=0.04,E32<=0.08),"SEHAT ✓",IF(AND(E32>=0.03,E32<=0.09),"PERHATIAN","BERISIKO ✗")) -> BERISIKO ✗ | L32: ⚠️ PERHATIAN: ~8,4% — melampaui batas atas 8%. Endowment dipakai terlalu cepat! Perlu dikurangi.
A33: 18 | B33: Investment Return | C33: Annual Investment Return ÷ Average Endowment | D33: Return Investasi / Rata-rata Endowment | E33: ='INPUT DATA'!B75/'INPUT DATA'!B50 -> 0.11538462 | F33: — | G33: — | H33: > 8%+Inflasi | I33: Positif | K33: =IF(E33>0.08,"SEHAT ✓",IF(E33>0.05,"PERHATIAN","BERISIKO ✗")) -> SEHAT ✓ | L33: PERHATIAN: ~10,5% — return masih baik ✓ tapi endowment terlalu kecil sehingga dampaknya minimal.
A34: 19 | B34: Endowment to Debt | C34: Total Endowment ÷ Total Debt | D34: Nilai Endowment / Total Utang | E34: ='INPUT DATA'!B39/'INPUT DATA'!B42 -> 0.36363636 | F34: ='INPUT DATA'!C39/'INPUT DATA'!C42 -> 0.345 | G34: ='INPUT DATA'!D39/'INPUT DATA'!D42 -> 0.32777778 | H34: > 2.0× | I34: > 1.0× | K34: =IF(E34>2,"SEHAT ✓",IF(E34>=1,"PERHATIAN","BERISIKO ✗")) -> BERISIKO ✗ | L34: 🔴 BERISIKO: 0,36× — endowment jauh lebih kecil dari total utang. Risiko jangka panjang serius.
A35: TABEL 6: RASIO PENDAPATAN DAN DIVERSIFIKASI
A36: No | B36: Nama Rasio / Indikator | C36: Formula | D36: Komponen Input | E36: Nilai TS | F36: Nilai TS-1 | G36: Nilai TS-2 | H36: Target Sehat | I36: Target Min/Max | J36: Score (0-100) | K36: Status TS | L36: Keterangan
A37: L1 | B37: ★ ★ Rasio Kemandirian Keuangan (RK) — LAMEMBA | C37: Pendapatan Non-Pemerintah ÷ Total Pendapatan | D37: Non-Pemerintah / Total Pendapatan | E37: ='INPUT DATA'!B15/'INPUT DATA'!B16 -> 0.86712408 | F37: ='INPUT DATA'!C15/'INPUT DATA'!C16 -> 0.86473584 | G37: ='INPUT DATA'!D15/'INPUT DATA'!D16 -> 0.86223473 | H37: ≥ 30% | I37: ≥ 30% | K37: =IF(E37>=0.3,"YA TERPENUHI ✓","BELUM TERPENUHI ✗") -> YA TERPENUHI ✓ | L37: LAMEMBA No.1. PERHATIAN: 86,71% — terpenuhi ✓.
A38: L6 | B38: ★ ★ Pertumbuhan Pendapatan Tahunan (GRR) — LAMEMBA | C38: ((Pendapatan TS − TS-1) ÷ TS-1) × 100 | D38: (Pdpt TS - TS-1) / TS-1 | E38: =('INPUT DATA'!B16-'INPUT DATA'!C16)/'INPUT DATA'!C16 -> 0.097814555 | F38: =('INPUT DATA'!C16-'INPUT DATA'!D16)/'INPUT DATA'!D16 -> 0.10517059 | G38: — | H38: ≥ 5% | I38: ≥ 5% | K38: =IF(E38>=0.05,"YA TERPENUHI ✓","BELUM TERPENUHI ✗") -> YA TERPENUHI ✓ | L38: LAMEMBA No.6. PERHATIAN: 9,78% ✓ — pertumbuhan terutama dari kenaikan SPP & mahasiswa.
A39: 20 | B39: Revenue Concentration | C39: Sumber Terbesar ÷ Total Revenue | D39: MAX sumber / Total Pendapatan | E39: =MAX('INPUT DATA'!B6,ABS('INPUT DATA'!B7),'INPUT DATA'!B8,'INPUT DATA'!B9,'INPUT DATA'!B10,'INPUT DATA'!B11,'INPUT DATA'!B12,'INPUT DATA'!B13)/'INPUT DATA'!B16 -> 0.81175106 | F39: =MAX('INPUT DATA'!C6,ABS('INPUT DATA'!C7),'INPUT DATA'!C8,'INPUT DATA'!C9,'INPUT DATA'!C10,'INPUT DATA'!C11,'INPUT DATA'!C12,'INPUT DATA'!C13)/'INPUT DATA'!C16 -> 0.82749841 | G39: =MAX('INPUT DATA'!D6,ABS('INPUT DATA'!D7),'INPUT DATA'!D8,'INPUT DATA'!D9,'INPUT DATA'!D10,'INPUT DATA'!D11,'INPUT DATA'!D12,'INPUT DATA'!D13)/'INPUT DATA'!D16 -> 0.84417868 | H39: 0.6 | I39: 0.7 | J39: =IF(E39<=H39,100,IF(E39>=0.7,0,(E39-0.7)/(H39-0.7)*100)) -> 0 | K39: =IF(E39<0.6,"SEHAT ✓",IF(E39<0.7,"PERHATIAN","BERISIKO ✗")) -> BERISIKO ✗ | L39: 🔴 BERISIKO: SPP Gross 81,2% dari total pendapatan — konsentrasi sangat tinggi. Risiko kritis jika enrollment turun.
A40: 21 | B40: Gift Revenue Ratio | C40: Total Gifts & Donations ÷ Total Revenue | D40: Donasi / Total Pendapatan | E40: ='INPUT DATA'!B10/'INPUT DATA'!B16 -> 0.048318516 | F40: ='INPUT DATA'!C10/'INPUT DATA'!C16 -> 0.045088054 | G40: ='INPUT DATA'!D10/'INPUT DATA'!D16 -> 0.042502052 | H40: 0.1 | I40: 0.01 | J40: =IF(E40>=H40,100,IF(E40<=0.01,0,(E40-0.01)/(H40-0.01)*100)) -> 42.576129 | K40: =IF(E40>0.1,"SEHAT ✓",IF(E40>0.05,"PERHATIAN","BERISIKO ✗")) -> BERISIKO ✗ | L40: ⚠️ PERHATIAN: 4,8% — di bawah 5%. Fundraising sangat terbatas. Perlu program alumni intensif.
...

Sheet IKK
A1: INDEKS KEBERLANJUTAN KEUANGAN (IKK) — LAMEMBA No.8 (PERHATIAN)
A2: ⚠️ PERHATIAN: IKK diperkirakan ≈ 2.57 — tepat di atas batas minimum ≥2.5. Perlu perbaikan segera.
A4: Komponen | B4: Nilai Rasio (TS) | C4: Nilai Maks Acuan | D4: Skor Dinormalisasi (0–1) | E4: Bobot | F4: Kontribusi
A5: Rasio Kemandirian (RK) | B5: ='HASIL RASIO'!E51 -> 0.86712408 | C5: 0.5 | D5: =MIN(1,MAX(0,B5/C5)) -> 1 | E5: 0.3 | F5: =D5*E5 -> 0.3
A6: Rasio Efisiensi Operasional (REO) | B6: ='HASIL RASIO'!E52 -> 0.58323208 | C6: 0.9 | D6: =MIN(1,MAX(0,B6/C6)) -> 0.64803564 | E6: 0.25 | F6: =D6*E6 -> 0.16200891
A7: Rasio Likuiditas (RL) | B7: ='HASIL RASIO'!E59 -> 1.7428571 | C7: 2 | D7: =MIN(1,MAX(0,B7/C7)) -> 0.87142857 | E7: 0.25 | F7: =D7*E7 -> 0.21785714
A8: Pertumbuhan Pendapatan (GRR) | B8: ='HASIL RASIO'!E56 -> 0.097814555 | C8: 0.2 | D8: =MIN(1,MAX(0,B8/C8)) -> 0.48907278 | E8: 0.2 | F8: =D8*E8 -> 0.097814555
A10: TOTAL BOBOT | E10: =SUM(E5:E8) -> 1 | F10: =SUM(F5:F8) -> 0.77768061
A12: IKK SKALA 0–4 ⚠️ Batas Min: ≥2.5 | B12: =F10*4 -> 3.1107224 | C12: Target: ≥ 2.5 | D12: =IF(B12>=2.5,"YA TERPENUHI ✓","BELUM TERPENUHI ✗") -> YA TERPENUHI ✓
A14: 3.5–4.0 | B14: Sangat Baik | C14: Fondasi keuangan sangat kuat
A15: 2.5–3.4 | B15: Baik (Terpenuhi LAMEMBA) | C15: Memenuhi standar, keuangan stabil
A16: 1.5–2.4 | B16: Perhatian | C16: Di bawah standar, perlu perbaikan
A17: 0–1.4 | B17: Berisiko | C17: Keuangan rentan, risiko tinggi

Sheet VARIANS ANGGARAN
A1: ANALISIS VARIANS ANGGARAN (VA) — LAMEMBA No.3 (PERHATIAN)
A2: ⚠️ PERHATIAN: VA ~7,6% — mendekati batas ±10%. Perlu penguatan sistem pengendalian anggaran.
A3: Pos Anggaran | B3: Rencana / RKAT | C3: Realisasi Aktual | D3: Varians (Rp) | E3: Varians (%) | F3: Status | G3: Catatan / Rekomendasi
A4: Total Pendapatan | B4: ='INPUT DATA'!B54 -> 38800000000 | C4: ='INPUT DATA'!C54 -> 41392000000 | D4: =C4-B4 -> 2592000000 | E4: =IF(B4=0,0,(C4-B4)/B4) -> 0.066804124 | F4: =IF(ABS(E4)<=0.1,"DALAM BATAS ✓","MELAMPAUI BATAS ✗") -> DALAM BATAS ✓ | G4: =IF(ABS(E4)<=0.1,"Varians dalam toleransi ±10%","Deviasi "&TEXT(E4,"0.00%")&" — wajib penjelasan & tindak lanjut") -> Varians dalam toleransi ±10%
A5: Biaya Operasional Langsung | B5: ='INPUT DATA'!B55 -> 22000000000 | C5: ='INPUT DATA'!C55 -> 24000000000 | D5: =C5-B5 -> 2000000000 | E5: =IF(B5=0,0,(C5-B5)/B5) -> 0.090909091 | F5: =IF(ABS(E5)<=0.1,"DALAM BATAS ✓","MELAMPAUI BATAS ✗") -> DALAM BATAS ✓ | G5: =IF(ABS(E5)<=0.1,"Varians dalam toleransi ±10%","Deviasi "&TEXT(E5,"0.00%")&" — wajib penjelasan & tindak lanjut") -> Varians dalam toleransi ±10%
A6: Pengembangan SDM | B6: ='INPUT DATA'!B56 -> 4800000000 | C6: ='INPUT DATA'!C56 -> 5200000000 | D6: =C6-B6 -> 400000000 | E6: =IF(B6=0,0,(C6-B6)/B6) -> 0.083333333 | F6: =IF(ABS(E6)<=0.1,"DALAM BATAS ✓","MELAMPAUI BATAS ✗") -> DALAM BATAS ✓ | G6: =IF(ABS(E6)<=0.1,"Varians dalam toleransi ±10%","Deviasi "&TEXT(E6,"0.00%")&" — wajib penjelasan & tindak lanjut") -> Varians dalam toleransi ±10%
A7: Investasi Sarpras (Aset+Pemeliharaan) | B7: ='INPUT DATA'!B57 -> 4200000000 | C7: ='INPUT DATA'!C57 -> 4600000000 | D7: =C7-B7 -> 400000000 | E7: =IF(B7=0,0,(C7-B7)/B7) -> 0.095238095 | F7: =IF(ABS(E7)<=0.1,"DALAM BATAS ✓","MELAMPAUI BATAS ✗") -> DALAM BATAS ✓ | G7: =IF(ABS(E7)<=0.1,"Varians dalam toleransi ±10%","Deviasi "&TEXT(E7,"0.00%")&" — wajib penjelasan & tindak lanjut") -> Varians dalam toleransi ±10%
A8: Biaya Administrasi | B8: ='INPUT DATA'!B58 -> 3650000000 | C8: ='INPUT DATA'!C58 -> 3800000000 | D8: =C8-B8 -> 150000000 | E8: =IF(B8=0,0,(C8-B8)/B8) -> 0.04109589 | F8: =IF(ABS(E8)<=0.1,"DALAM BATAS ✓","MELAMPAUI BATAS ✗") -> DALAM BATAS ✓ | G8: =IF(ABS(E8)<=0.1,"Varians dalam toleransi ±10%","Deviasi "&TEXT(E8,"0.00%")&" — wajib penjelasan & tindak lanjut") -> Varians dalam toleransi ±10%
A9: Total Pengeluaran | B9: ='INPUT DATA'!B59 -> 38400000000 | C9: ='INPUT DATA'!C59 -> 41150000000 | D9: =C9-B9 -> 2750000000 | E9: =IF(B9=0,0,(C9-B9)/B9) -> 0.071614583 | F9: =IF(ABS(E9)<=0.1,"DALAM BATAS ✓","MELAMPAUI BATAS ✗") -> DALAM BATAS ✓ | G9: =IF(ABS(E9)<=0.1,"Varians dalam toleransi ±10%","Deviasi "&TEXT(E9,"0.00%")&" — wajib penjelasan & tindak lanjut") -> Varians dalam toleransi ±10%
A11: RATA-RATA VARIANS ABSOLUT (LAMEMBA ≤ ±10%) | E11: ='INPUT DATA'!E60 -> 0.074832519 | F11: =IF(E11<=0.1,"LAMEMBA: TERPENUHI ✓","LAMEMBA: BELUM TERPENUHI ✗") -> LAMEMBA: TERPENUHI ✓

Sheet TRIDHARMA ATT
A1: ALOKASI TRIDHARMA TERIMBANG (ATT) — LAMEMBA No.10 (PERHATIAN)
A2: PERHATIAN: Alokasi Pend58%/Rist28%/PkM14% — deviasi semua < 10% dari bobot LAMEMBA ✓
A3: Fungsi Tridharma | B3: ='INPUT DATA'!B20 -> 24000000000 | C3: Bobot LAMEMBA | D3: Kontribusi Terbobot | E3: Proporsi Aktual (%) | F3: Evaluasi
A4: Pendidikan | B4: ='INPUT DATA'!B64 -> 13920000000 | C4: 0.5 | D4: =B4*C4 -> 6960000000 | E4: =IF(SUM($B$4:$B$6)=0,0,B4/SUM($B$4:$B$6)) -> 0.58 | F4: =IF(ABS(E4-C4)<=0.1,"Proporsional ✓","Perlu rebalancing — selisih "&TEXT(ABS(E4-C4),"0.0%")) -> Proporsional ✓ | G4: =IF(F4="Proporsional ✓",1,0) -> 1
A5: Penelitian | B5: ='INPUT DATA'!B65 -> 6720000000 | C5: 0.3 | D5: =B5*C5 -> 2016000000 | E5: =IF(SUM($B$4:$B$6)=0,0,B5/SUM($B$4:$B$6)) -> 0.28 | F5: =IF(ABS(E5-C5)<=0.1,"Proporsional ✓","Perlu rebalancing — selisih "&TEXT(ABS(E5-C5),"0.0%")) -> Proporsional ✓ | G5: =IF(F5="Proporsional ✓",1,0) -> 1
A6: Pengabdian kepada Masyarakat (PkM) | B6: ='INPUT DATA'!B66 -> 3360000000 | C6: 0.2 | D6: =B6*C6 -> 672000000 | E6: =IF(SUM($B$4:$B$6)=0,0,B6/SUM($B$4:$B$6)) -> 0.14 | F6: =IF(ABS(E6-C6)<=0.1,"Proporsional ✓","Perlu rebalancing — selisih "&TEXT(ABS(E6-C6),"0.0%")) -> Proporsional ✓ | G6: =IF(F6="Proporsional ✓",1,0) -> 1
A7: TOTAL | B7: =SUM(B4:B6) -> 24000000000 | C7: =SUM(C4:C6) -> 1 | D7: =SUM(D4:D6) -> 9648000000 | E7: =SUM(E4:E6) -> 1
A9: INDEKS ATT | B9: =SUM(G4:G6)/3 -> 1 | C9: Target: ~1.0 | D9: =IF(B9=1,"YA TERPENUHI ✓","PERLU PENYESUAIAN") -> YA TERPENUHI ✓

Sheet SCORECARD CFI
A1: SCORECARD KESEHATAN KEUANGAN GABUNGAN (CFI + LAMEMBA) — PREDIKAT PERHATIAN
A3: Kategori | B3: Bobot | C3: Rasio Kunci | D3: Skor (0–100) | E3: IKK Acuan | F3: PIC
A4: Kekuatan Finansial | B4: 0.35 | C4: Primary Reserve, Viability, Return on NA | D4: =AVERAGE('HASIL RASIO'!J5:J8) -> 52.516532 | E4: ≤1.4 | F4: CFO
A5: Likuiditas | B5: 0.25 | C5: Liquidity Ratio, Days Cash, ★ RL | D5: =AVERAGE('HASIL RASIO'!J11:J13) -> 100 | E5: ≤1.0 | F5: Treasurer
A6: Efisiensi Operasi | B6: 0.2 | C6: Operating Margin, ★ REO, Admin Ratio, ★ VA | D6: =AVERAGE('HASIL RASIO'!J17:J19) -> 57.461989 | E6: ≤0.8 | F6: Budget Dir.
A7: Manajemen Utang | B7: 0.15 | C7: DSCR, Debt/Assets, Interest Coverage | D7: =AVERAGE('HASIL RASIO'!J25:J27) -> 35.191919 | E7: ≤0.6 | F7: CFO
A8: Diversifikasi Pendapatan | B8: 0.05 | C8: ★ RK, Revenue Concentration, Gift Revenue, ★ GRR | D8: =AVERAGE('HASIL RASIO'!J39:J41) -> 47.525376 | E8: ≤0.2 | F8: CFO
A9: TOTAL | B9: 100% | D9: =(B4*D4)+(B5*D5)+(B6*D6)+(B7*D7)+(B8*D8) -> 62.528241 | F9: =IF(D9>=85,"Sangat Baik ✓",IF(D9>=70,"Baik ✓",IF(D9>=50,"Perhatian","Berisiko ✗"))) -> Perhatian

Sheet DASHBOARD
A1: DASHBOARD KESEHATAN KEUANGAN ⚠️ PREDIKAT PERHATIAN — 2024/2025
A2: ⚠️ PTS Menengah-Kecil, 2.800 Mhs, SPP Rp 6 jt/sem. Total Pdpt Rp 41,4 M. Margin 0,58%. Tindakan perbaikan diperlukan.
B4: Indikator LAMEMBA Terpenuhi | D4: Tingkat Pemenuhan LAMEMBA | G4: IKK (Target ≥ 2.5) | J4: Operating Margin (Target ≥ 2%)
B5: ='HASIL RASIO'!E62 -> 6 | D5: ='HASIL RASIO'!F62 -> 0.6 | G5: =IKK!B12 -> 3.1107224 | J5: =('INPUT DATA'!B16-'INPUT DATA'!B30)/'INPUT DATA'!B16 -> 0.0058465404
A7: 10 INDIKATOR LAMEMBA — STATUS ⚠️ PERHATIAN
B8: L1 | C8: ='HASIL RASIO'!B51 -> ★ ★ Rasio Kemandirian Keuangan (RK) | D8: ='HASIL RASIO'!E51 -> 0.86712408 | E8: ='HASIL RASIO'!K51 -> YA TERPENUHI ✓ | H8: L6 | I8: ='HASIL RASIO'!B56 -> ★ ★ Pertumbuhan Pendapatan Tahunan (GRR) | J8: ='HASIL RASIO'!E56 -> 0.097814555 | K8: ='HASIL RASIO'!K56 -> YA TERPENUHI ✓
B9: L2 | C9: ='HASIL RASIO'!B52 -> ★ ★ Rasio Efisiensi Operasional (REO) | D9: ='HASIL RASIO'!E52 -> 0.58323208 | E9: ='HASIL RASIO'!K52 -> BELUM TERPENUHI ✗ | H9: L7 | I9: ='HASIL RASIO'!B57 -> ★ ★ Rasio Biaya per Mahasiswa (RBM) | J9: ='HASIL RASIO'!E57 -> 14696429 | K9: ='HASIL RASIO'!K57 -> "Lihat SPMI institusi"
B10: L3 | C10: ='HASIL RASIO'!B53 -> ★ ★ Varians Anggaran (VA) | D10: ='HASIL RASIO'!E53 -> 0.074832519 | E10: ='HASIL RASIO'!K53 -> YA TERPENUHI ✓ | H10: L8 | I10: ='HASIL RASIO'!B58 -> ★ ★ Indeks Keberlanjutan Keuangan (IKK) | J10: =IKK!B12 -> 3.1107224 | K10: ='HASIL RASIO'!K58 -> YA TERPENUHI ✓
B11: L4 | C11: ='HASIL RASIO'!B54 -> ★ ★ Rasio Investasi SDM (RISDM) | D11: ='HASIL RASIO'!E54 -> 0.12636695 | E11: ='HASIL RASIO'!K54 -> BELUM TERPENUHI ✗ | H11: L9 | I11: ='HASIL RASIO'!B59 -> ★ ★ Rasio Likuiditas Keuangan (RL) | J11: ='HASIL RASIO'!E59 -> 1.7428571 | K11: ='HASIL RASIO'!K59 -> YA TERPENUHI ✓
B12: L5 | C12: ='HASIL RASIO'!B55 -> ★ ★ Rasio Investasi Sarpras (RISP) | D12: ='HASIL RASIO'!E55 -> 0.11178615 | E12: ='HASIL RASIO'!K55 -> BELUM TERPENUHI ✗ | H12: L10 | I12: ='HASIL RASIO'!B60 -> ★ ★ Alokasi Tridharma Terimbang (ATT) | J12: ='HASIL RASIO'!E60 -> 1 | K12: ='HASIL RASIO'!K60 -> YA TERPENUHI ✓
A14: RINGKASAN 29 RASIO KEUANGAN — PERHATIAN KHUSUS pada yang Merah/Kuning
B15: No | C15: Rasio | D15: Nilai TS | E15: Target | F15: Status | G15: Ket. | H15: No | I15: Rasio | J15: Nilai TS | K15: Target | L15: Status
B16: 1 | C16: Primary Reserve | D16: ='HASIL RASIO'!E5 -> 0.43742406 | E16: ≥0.40 | F16: ='HASIL RASIO'!K5 -> SEHAT ✓ | H16: 15 | I16: Debt/Student | J16: ='HASIL RASIO'!E28 -> 7857142.9 | K16: Bench. | L16: ='HASIL RASIO'!K28 -> "Lihat benchmark industri"
B17: 2 | C17: Viability Ratio | D17: ='HASIL RASIO'!E6 -> 0.81818182 | E17: ≥0.35 | F17: ='HASIL RASIO'!K6 -> SEHAT ✓ | H17: 16 | I17: Endow./Student⚠️ | J17: ='HASIL RASIO'!E31 -> 2857142.9 | K17: Var. | L17: ='HASIL RASIO'!K31 -> "Lihat benchmark kategori"
B18: 3 | C18: Return on NA | D18: ='HASIL RASIO'!E7 -> 0.014285714 | E18: >2% | F18: ='HASIL RASIO'!K7 -> PERHATIAN | H18: 17 | I18: Endow.Spend⚠️ | J18: ='HASIL RASIO'!E32 -> 0.092307692 | K18: 4-6% | L18: ='HASIL RASIO'!K32 -> BERISIKO ✗
B19: 4 | C19: Net Op.Revenue | D19: ='HASIL RASIO'!E8 -> 0.0058465404 | E19: >2% | F19: ='HASIL RASIO'!K8 -> PERHATIAN | H19: 18 | I19: Invest.Return | J19: ='HASIL RASIO'!E33 -> 0.11538462 | K19: >8% | L19: ='HASIL RASIO'!K33 -> SEHAT ✓
B20: 5 | C20: Liquidity Ratio | D20: ='HASIL RASIO'!E11 -> 1.75 | E20: ≥1.25 | F20: ='HASIL RASIO'!K11 -> SEHAT ✓ | H20: 19 | I20: Endow/Debt 🔴 | J20: ='HASIL RASIO'!E34 -> 0.36363636 | K20: >2× | L20: ='HASIL RASIO'!K34 -> BERISIKO ✗
B21: 6 | C21: Days Cash | D21: ='HASIL RASIO'!E12 -> 159.65978 | E21: ≥120 hr | F21: ='HASIL RASIO'!K12 -> SEHAT ✓ | H21: 20 | I21: Rev.Conc. 🔴 | J21: ='HASIL RASIO'!E39 -> 0.81175106 | K21: <60% | L21: ='HASIL RASIO'!K39 -> BERISIKO ✗
B22: 7 | C22: Cash to Debt | D22: ='HASIL RASIO'!E13 -> 0.47727273 | E22: >0.25 | F22: ='HASIL RASIO'!K13 -> SEHAT ✓ | H22: 21 | I22: Gift Revenue⚠️ | J22: ='HASIL RASIO'!E40 -> 0.048318516 | K22: >10% | L22: ='HASIL RASIO'!K40 -> BERISIKO ✗
B23: 8 | C23: Operating Margin | D23: ='HASIL RASIO'!E17 -> 0.0058465404 | E23: ≥4% | F23: ='HASIL RASIO'!K17 -> PERHATIAN | H23: 22 | I23: Research Rev. | J23: ='HASIL RASIO'!E41 -> 0.10146888 | K23: >10% | L23: ='HASIL RASIO'!K41 -> SEHAT ✓
B24: 9 | C24: Admin Expense | D24: ='HASIL RASIO'!E18 -> 0.092345079 | E24: <15% | F24: ='HASIL RASIO'!K18 -> SEHAT ✓ | H24: 23 | I24: Auxiliary Rev.⚠️ | J24: ='HASIL RASIO'!E42 -> 0.09180518 | K24: 15-25% | L24: ='HASIL RASIO'!K42 -> PERHATIAN
B25: 10 | C25: Tuition Depend. | D25: ='HASIL RASIO'!E19 -> 0.58446077 | E25: <70% | F25: ='HASIL RASIO'!K19 -> RISIKO SEDANG | H25: 24 | I25: SFR | J25: ='HASIL RASIO'!E45 -> 15.135135 | K25: 12-20 | L25: ='HASIL RASIO'!K45 -> SEHAT ✓
B26: 11 | C26: Cost/Student | D26: ='HASIL RASIO'!E20 -> 14696429 | E26: SPMI | F26: ='HASIL RASIO'!K20 -> "Lihat benchmark SPMI" | H26: 25 | I26: Discount Rate | J26: ='HASIL RASIO'!E46 -> 0.28 | K26: 30-50% | L26: ='HASIL RASIO'!K46 -> PERHATIAN
B27: 12 | C27: DSCR ⚠️ | D27: ='HASIL RASIO'!E25 -> 1.2918182 | E27: ≥2× | F27: ='HASIL RASIO'!K25 -> PERHATIAN | H27: 26 | I27: Net Tuit/Stud | J27: ='HASIL RASIO'!E47 -> 8640000 | K27: Naik | L27: ='HASIL RASIO'!K47 -> STABIL
B28: 13 | C28: Debt/Assets ⚠️ | D28: ='HASIL RASIO'!E26 -> 0.24336283 | E28: <25% | F28: ='HASIL RASIO'!K26 -> SEHAT ✓ | H28: 27 | I28: Faculty Cost | J28: ='HASIL RASIO'!E48 -> 0.4835966 | K28: 45-55% | L28: ='HASIL RASIO'!K48 -> SEHAT ✓
B29: 14 | C29: Interest Cov.⚠️ | D29: ='HASIL RASIO'!E27 -> 1.77625 | E29: ≥3× | F29: ='HASIL RASIO'!K27 -> BERISIKO ✗

Sheet JADWAL MONITORING
A1: JADWAL MONITORING — PERHATIAN (Intensitas Lebih Tinggi)
A2: ⚠️ PERHATIAN memerlukan monitoring lebih intensif. Rasio kritis (DSCR, ICR, Margin, RISDM, RISP) dipantau bulanan.
A3: Nama Rasio / Indikator | B3: Frekuensi | C3: PIC | D3: Bulanan | E3: Kuartalan | F3: Tahunan | G3: Tindakan Prioritas
A4: Primary Reserve Ratio | B4: Bulanan | C4: CFO | D4: ✓ | G4: Pantau tren — jika <0.40 perlu respons cepat
A5: Viability Ratio | B5: Bulanan | C5: CFO | D5: ✓ | G5: Pantau terhadap pertumbuhan utang
A6: Return on Net Assets | B6: Kuartalan | C6: CFO | E6: ✓ | G6: Target >2% melalui peningkatan surplus
A7: Net Op. Revenue Ratio ⚠️ | B7: Bulanan | C7: CFO/Budget | D7: ✓ | G7: KRITIS: Margin 0,58% sangat rentan
A8: Liquidity Ratio | B8: Bulanan | C8: Treasurer | D8: ✓ | G8: Pantau ketersediaan kas jangka pendek
A9: Days Cash on Hand | B9: Bulanan | C9: Treasurer | D9: ✓ | G9: Pantau apakah turun di bawah 120 hari
A10: Cash to Debt Ratio | B10: Bulanan | C10: CFO | D10: ✓ | G10: Monitor keseimbangan kas vs utang
A11: ★ Rasio Likuiditas (RL) — LAMEMBA | B11: Bulanan | C11: CFO | D11: ✓ | G11: Pantau agar tetap ≥1.0×
A12: Operating Margin ⚠️ | B12: Bulanan | C12: Budget Dir. | D12: ✓ | G12: KRITIS: Tingkatkan ke 2-3% dalam 2 tahun
A13: Admin Expense Ratio | B13: Bulanan | C13: CFO | D13: ✓ | G13: Efisiensi overhead — target <8%
A14: Tuition Dependency ⚠️ | B14: Kuartalan | C14: CFO | E14: ✓ | G14: Target turun ke <55% melalui diversifikasi
A15: Cost per Student / ★ RBM | B15: Kuartalan | C15: Budget Dir. | E15: ✓ | G15: Bandingkan dengan SPMI secara berkala
A16: ★ REO — LAMEMBA | B16: Kuartalan | C16: CFO | E16: ✓ | G16: Tingkatkan secara bertahap
A17: DSCR ⚠️ 🔴 | B17: Bulanan | C17: CFO | D17: ✓ | G17: KRITIS: 1,29× — di bawah 2,0×. Prioritas utama
A18: Debt-to-Assets ⚠️ | B18: Bulanan | C18: CFO | D18: ✓ | G18: Mendekati 25% — jangan tambah utang baru
A19: Interest Coverage ⚠️ | B19: Bulanan | C19: CFO | D19: ✓ | G19: 1,78× — pantau ketat agar tidak turun lagi
A20: Debt per Student | B20: Kuartalan | C20: CFO | E20: ✓ | G20: Monitor tren per mahasiswa
A21: Endowment per Student ⚠️ | B21: Tahunan | C21: CIO/CFO | F21: ✓ | G21: Target gandakan dalam 5 tahun
A22: Endowment Spending Rate ⚠️ | B22: Kuartalan | C22: CIO | E22: ✓ | G22: KRITIS: 8,4% — kurangi ke 4-6%
A23: Investment Return | B23: Tahunan | C23: CIO | F23: ✓ | G23: Return baik — tambah modal endowment
A24: Endowment to Debt 🔴 | B24: Kuartalan | C24: CFO/CIO | E24: ✓ | G24: KRITIS: 0,36× — kembangkan endowment
A25: ★ RK Kemandirian — LAMEMBA | B25: Tahunan | C25: CFO | F25: ✓ | G25: Pertahankan, diversifikasi sumber
A26: ★ GRR Pertumbuhan — LAMEMBA | B26: Tahunan | C26: CFO | F26: ✓ | G26: Pastikan pertumbuhan bukan hanya dari SPP
A27: Revenue Concentration 🔴 | B27: Kuartalan | C27: CFO | E27: ✓ | G27: KRITIS: 81% SPP — diversifikasi mendesak
A28: Gift Revenue ⚠️ | B28: Kuartalan | C28: Dev.Office | E28: ✓ | G28: Kembangkan program alumni giving
A29: Research Revenue | B29: Kuartalan | C29: Research | E29: ✓ | G29: Tingkatkan kapasitas riset dosen
A30: Auxiliary Revenue ⚠️ | B30: Kuartalan | C30: CFO | E30: ✓ | G30: Kembangkan unit usaha kampus
A31: Student-to-Faculty Ratio | B31: Semesteran | C31: Akademik | E31: ✓ | G31: Pertahankan di 12-20:1
A32: Discount Rate | B32: Semesteran | C32: Fin.Aid | E32: ✓ | G32: Tingkatkan ke 30-40% untuk rekrutmen
A33: Net Tuition per Student | B33: Tahunan | C33: CFO | F33: ✓ | G33: Pantau tren naik/turun
A34: Faculty Cost Ratio | B34: Kuartalan | C34: HR/CFO | E34: ✓ | G34: Jaga di 45-55%
A35: ★ RISDM — LAMEMBA ⚠️ | B35: Bulanan | C35: HR/CFO | D35: ✓ | G35: KRITIS: 12,6% — harus ≥15%
A36: ★ RISP — LAMEMBA ⚠️ | B36: Bulanan | C36: CFO | D36: ✓ | G36: KRITIS: 11,2% — harus ≥20%
A37: ★ Varians Anggaran (VA) | B37: Bulanan | C37: Budget Dir. | D37: ✓ | G37: Perketat pengendalian — mendekati 10%
A38: ★ IKK — LAMEMBA | B38: Kuartalan | C38: CFO | E38: ✓ | G38: Pantau agar tidak turun di bawah 2,5
A39: ★ Alokasi Tridharma (ATT) | B39: Tahunan | C39: CFO/Warek I | F39: ✓ | G39: Pertahankan proporsionalitas
